Workbook

Sheet Lançamento
A1: PLANILHA DE LANÇAMENTO OFICIAL - TAXA DE ATENDIMENTO LOGÍSTICO (SLA / OTIF)
A3: Ano de referência: | B3: 2026 | G3: Verde a partir de: | H3: 0.95 | J3: Laranja a partir de: | K3: 0.9 | M3: Eixo a partir de: | N3: 0
A4: Preencha só as células brancas (JAN a DEZ e META): digite 98,4 para 98,4%. Cor do número = farol pelos limites acima | Fundo amarelo = taxa sem evidência | Cinza = calculado
A5: MONTADORA | B5: JAN | C5: FEV | D5: MAR | E5: ABR | F5: MAI | G5: JUN | H5: JUL | I5: AGO | J5: SET | K5: OUT | L5: NOV | M5: DEZ | N5: META | O5: MÉDIA YTD | P5: EVIDÊNCIAS
A6: Renault | N6: 1 | O6: =IF(COUNT(B6:M6)=0,"",AVERAGE(B6:M6)) | P6: =IF($A6="","",COUNTIFS('Evidências'!$A$6:$A$405,$A6,'Evidências'!$B$6:$B$405,">0")&"/"&COUNT(B6:M6))
A7: Mercedes-Benz | N7: 1 | O7: =IF(COUNT(B7:M7)=0,"",AVERAGE(B7:M7)) | P7: =IF($A7="","",COUNTIFS('Evidências'!$A$6:$A$405,$A7,'Evidências'!$B$6:$B$405,">0")&"/"&COUNT(B7:M7))
A8: Stellantis | N8: 1 | O8: =IF(COUNT(B8:M8)=0,"",AVERAGE(B8:M8)) | P8: =IF($A8="","",COUNTIFS('Evidências'!$A$6:$A$405,$A8,'Evidências'!$B$6:$B$405,">0")&"/"&COUNT(B8:M8))
A9: Volvo | N9: 1 | O9: =IF(COUNT(B9:M9)=0,"",AVERAGE(B9:M9)) | P9: =IF($A9="","",COUNTIFS('Evidências'!$A$6:$A$405,$A9,'Evidências'!$B$6:$B$405,">0")&"/"&COUNT(B9:M9))
A10: Scania | N10: 1 | O10: =IF(COUNT(B10:M10)=0,"",AVERAGE(B10:M10)) | P10: =IF($A10="","",COUNTIFS('Evidências'!$A$6:$A$405,$A10,'Evidências'!$B$6:$B$405,">0")&"/"&COUNT(B10:M10))
A11: Iveco | N11: 1 | O11: =IF(COUNT(B11:M11)=0,"",AVERAGE(B11:M11)) | P11: =IF($A11="","",COUNTIFS('Evidências'!$A$6:$A$405,$A11,'Evidências'!$B$6:$B$405,">0")&"/"&COUNT(B11:M11))
A12: HORSE | N12: 1 | O12: =IF(COUNT(B12:M12)=0,"",AVERAGE(B12:M12)) | P12: =IF($A12="","",COUNTIFS('Evidências'!$A$6:$A$405,$A12,'Evidências'!$B$6:$B$405,">0")&"/"&COUNT(B12:M12))
A13: Nissan | N13: 1 | O13: =IF(COUNT(B13:M13)=0,"",AVERAGE(B13:M13)) | P13: =IF($A13="","",COUNTIFS('Evidências'!$A$6:$A$405,$A13,'Evidências'!$B$6:$B$405,">0")&"/"&COUNT(B13:M13))
O14: =IF(COUNT(B14:M14)=0,"",AVERAGE(B14:M14)) | P14: =IF($A14="","",COUNTIFS('Evidências'!$A$6:$A$405,$A14,'Evidências'!$B$6:$B$405,">0")&"/"&COUNT(B14:M14))
O15: =IF(COUNT(B15:M15)=0,"",AVERAGE(B15:M15)) | P15: =IF($A15="","",COUNTIFS('Evidências'!$A$6:$A$405,$A15,'Evidências'!$B$6:$B$405,">0")&"/"&COUNT(B15:M15))
O16: =IF(COUNT(B16:M16)=0,"",AVERAGE(B16:M16)) | P16: =IF($A16="","",COUNTIFS('Evidências'!$A$6:$A$405,$A16,'Evidências'!$B$6:$B$405,">0")&"/"&COUNT(B16:M16))
O17: =IF(COUNT(B17:M17)=0,"",AVERAGE(B17:M17)) | P17: =IF($A17="","",COUNTIFS('Evidências'!$A$6:$A$405,$A17,'Evidências'!$B$6:$B$405,">0")&"/"&COUNT(B17:M17))
O18: =IF(COUNT(B18:M18)=0,"",AVERAGE(B18:M18)) | P18: =IF($A18="","",COUNTIFS('Evidências'!$A$6:$A$405,$A18,'Evidências'!$B$6:$B$405,">0")&"/"&COUNT(B18:M18))
O19: =IF(COUNT(B19:M19)=0,"",AVERAGE(B19:M19)) | P19: =IF($A19="","",COUNTIFS('Evidências'!$A$6:$A$405,$A19,'Evidências'!$B$6:$B$405,">0")&"/"&COUNT(B19:M19))
O20: =IF(COUNT(B20:M20)=0,"",AVERAGE(B20:M20)) | P20: =IF($A20="","",COUNTIFS('Evidências'!$A$6:$A$405,$A20,'Evidências'!$B$6:$B$405,">0")&"/"&COUNT(B20:M20))
O21: =IF(COUNT(B21:M21)=0,"",AVERAGE(B21:M21)) | P21: =IF($A21="","",COUNTIFS('Evidências'!$A$6:$A$405,$A21,'Evidências'!$B$6:$B$405,">0")&"/"&COUNT(B21:M21))
O22: =IF(COUNT(B22:M22)=0,"",AVERAGE(B22:M22)) | P22: =IF($A22="","",COUNTIFS('Evidências'!$A$6:$A$405,$A22,'Evidências'!$B$6:$B$405,">0")&"/"&COUNT(B22:M22))
O23: =IF(COUNT(B23:M23)=0,"",AVERAGE(B23:M23)) | P23: =IF($A23="","",COUNTIFS('Evidências'!$A$6:$A$405,$A23,'Evidências'!$B$6:$B$405,">0")&"/"&COUNT(B23:M23))
O24: =IF(COUNT(B24:M24)=0,"",AVERAGE(B24:M24)) | P24: =IF($A24="","",COUNTIFS('Evidências'!$A$6:$A$405,$A24,'Evidências'!$B$6:$B$405,">0")&"/"&COUNT(B24:M24))
O25: =IF(COUNT(B25:M25)=0,"",AVERAGE(B25:M25)) | P25: =IF($A25="","",COUNTIFS('Evidências'!$A$6:$A$405,$A25,'Evidências'!$B$6:$B$405,">0")&"/"&COUNT(B25:M25))
... O35: =IF(COUNT(B35:M35)=0,"",AVERAGE(B35:M35)) | P35: =IF($A35="","",COUNTIFS('Evidências'!$A$6:$A$405,$A35,'Evidências'!$B$6:$B$405,">0")&"/"&COUNT(B35:M35))

Sheet Gráficos
A1: ="INDICADORES DE PERFORMANCE LOGÍSTICA (SLA / OTIF) - ANUAL "&'Lançamento'!B3
B3: ="Verde: ≥ "&ROUND('Lançamento'!H3*100,1)&"%" | H3: ="Laranja: ≥ "&ROUND('Lançamento'!K3*100,1)&"% e < "&ROUND('Lançamento'!H3*100,1)&"%" | O3: ="Vermelho: < "&ROUND('Lançamento'!K3*100,1)&"%" | T3: - - - | U3: Meta (linha tracejada) | Z3: —— | AA3: Tendência: média móvel de 3 meses
A5: MÉDIA GERAL YTD | G5: =IF(Aux!B2=0,"NO VERDE NO ÚLTIMO MÊS","NO VERDE (≥"&ROUND('Lançamento'!$H$3*100,1)&"%) EM "&CHOOSE(Aux!B2,"JAN","FEV","MAR","ABR","MAI","JUN","JUL","AGO","SET","OUT","NOV","DEZ")) | M5: MAIOR MÉDIA YTD | S5: MENOR MÉDIA YTD | Y5: TAXAS SEM EVIDÊNCIA
A6: =IFERROR(AVERAGE('Lançamento'!O6:O35),"-") | G6: =IF(Aux!B2=0,"-",Aux!B3&" de "&Aux!B4) | M6: =IFERROR(INDEX('Lançamento'!A6:A35,MATCH(MAX('Lançamento'!O6:O35),'Lançamento'!O6:O35,0))&" "&ROUND(MAX('Lançamento'!O6:O35)*100,1)&"%","-") | S6: =IFERROR(INDEX('Lançamento'!A6:A35,MATCH(MIN('Lançamento'!O6:O35),'Lançamento'!O6:O35,0))&" "&ROUND(MIN('Lançamento'!O6:O35)*100,1)&"%","-") | Y6: =MAX(0,COUNT('Lançamento'!B6:M35)-SUMPRODUCT(--('Evidências'!A6:A405<>"")))
A8: MAPA DE CALOR - TAXA DE ATENDIMENTO MENSAL POR MONTADORA
A9: MONTADORA | E9: JAN | G9: FEV | I9: MAR | K9: ABR | M9: MAI | O9: JUN | Q9: JUL | S9: AGO | U9: SET | W9: OUT | Y9: NOV | AA9: DEZ | AC9: MÉDIA YTD
A10: =IF('Lançamento'!A6="","",'Lançamento'!A6) | E10: =IF(ISNUMBER('Lançamento'!B6),'Lançamento'!B6,"") | G10: =IF(ISNUMBER('Lançamento'!C6),'Lançamento'!C6,"") | I10: =IF(ISNUMBER('Lançamento'!D6),'Lançamento'!D6,"") | K10: =IF(ISNUMBER('Lançamento'!E6),'Lançamento'!E6,"") | M10: =IF(ISNUMBER('Lançamento'!F6),'Lançamento'!F6,"") | O10: =IF(ISNUMBER('Lançamento'!G6),'Lançamento'!G6,"") | Q10: =IF(ISNUMBER('Lançamento'!H6),'Lançamento'!H6,"") | S10: =IF(ISNUMBER('Lançamento'!I6),'Lançamento'!I6,"") | U10: =IF(ISNUMBER('Lançamento'!J6),'Lançamento'!J6,"") | W10: =IF(ISNUMBER('Lançamento'!K6),'Lançamento'!K6,"") | Y10: =IF(ISNUMBER('Lançamento'!L6),'Lançamento'!L6,"") | AA10: =IF(ISNUMBER('Lançamento'!M6),'Lançamento'!M6,"") | AC10: =IF(ISNUMBER('Lançamento'!O6),'Lançamento'!O6,"")
A11: =IF('Lançamento'!A7="","",'Lançamento'!A7) | E11: =IF(ISNUMBER('Lançamento'!B7),'Lançamento'!B7,"") | G11: =IF(ISNUMBER('Lançamento'!C7),'Lançamento'!C7,"") | I11: =IF(ISNUMBER('Lançamento'!D7),'Lançamento'!D7,"") | K11: =IF(ISNUMBER('Lançamento'!E7),'Lançamento'!E7,"") | M11: =IF(ISNUMBER('Lançamento'!F7),'Lançamento'!F7,"") | O11: =IF(ISNUMBER('Lançamento'!G7),'Lançamento'!G7,"") | Q11: =IF(ISNUMBER('Lançamento'!H7),'Lançamento'!H7,"") | S11: =IF(ISNUMBER('Lançamento'!I7),'Lançamento'!I7,"") | U11: =IF(ISNUMBER('Lançamento'!J7),'Lançamento'!J7,"") | W11: =IF(ISNUMBER('Lançamento'!K7),'Lançamento'!K7,"") | Y11: =IF(ISNUMBER('Lançamento'!L7),'Lançamento'!L7,"") | AA11: =IF(ISNUMBER('Lançamento'!M7),'Lançamento'!M7,"") | AC11: =IF(ISNUMBER('Lançamento'!O7),'Lançamento'!O7,"")
A12: =IF('Lançamento'!A8="","",'Lançamento'!A8) | E12: =IF(ISNUMBER('Lançamento'!B8),'Lançamento'!B8,"") | G12: =IF(ISNUMBER('Lançamento'!C8),'Lançamento'!C8,"") | I12: =IF(ISNUMBER('Lançamento'!D8),'Lançamento'!D8,"") | K12: =IF(ISNUMBER('Lançamento'!E8),'Lançamento'!E8,"") | M12: =IF(ISNUMBER('Lançamento'!F8),'Lançamento'!F8,"") | O12: =IF(ISNUMBER('Lançamento'!G8),'Lançamento'!G8,"") | Q12: =IF(ISNUMBER('Lançamento'!H8),'Lançamento'!H8,"") | S12: =IF(ISNUMBER('Lançamento'!I8),'Lançamento'!I8,"") | U12: =IF(ISNUMBER('Lançamento'!J8),'Lançamento'!J8,"") | W12: =IF(ISNUMBER('Lançamento'!K8),'Lançamento'!K8,"") | Y12: =IF(ISNUMBER('Lançamento'!L8),'Lançamento'!L8,"") | AA12: =IF(ISNUMBER('Lançamento'!M8),'Lançamento'!M8,"") | AC12: =IF(ISNUMBER('Lançamento'!O8),'Lançamento'!O8,"")
A13: =IF('Lançamento'!A9="","",'Lançamento'!A9) | E13: =IF(ISNUMBER('Lançamento'!B9),'Lançamento'!B9,"") | G13: =IF(ISNUMBER('Lançamento'!C9),'Lançamento'!C9,"") | I13: =IF(ISNUMBER('Lançamento'!D9),'Lançamento'!D9,"") | K13: =IF(ISNUMBER('Lançamento'!E9),'Lançamento'!E9,"") | M13: =IF(ISNUMBER('Lançamento'!F9),'Lançamento'!F9,"") | O13: =IF(ISNUMBER('Lançamento'!G9),'Lançamento'!G9,"") | Q13: =IF(ISNUMBER('Lançamento'!H9),'Lançamento'!H9,"") | S13: =IF(ISNUMBER('Lançamento'!I9),'Lançamento'!I9,"") | U13: =IF(ISNUMBER('Lançamento'!J9),'Lançamento'!J9,"") | W13: =IF(ISNUMBER('Lançamento'!K9),'Lançamento'!K9,"") | Y13: =IF(ISNUMBER('Lançamento'!L9),'Lançamento'!L9,"") | AA13: =IF(ISNUMBER('Lançamento'!M9),'Lançamento'!M9,"") | AC13: =IF(ISNUMBER('Lançamento'!O9),'Lançamento'!O9,"")
A14: =IF('Lançamento'!A10="","",'Lançamento'!A10) | E14: =IF(ISNUMBER('Lançamento'!B10),'Lançamento'!B10,"") | G14: =IF(ISNUMBER('Lançamento'!C10),'Lançamento'!C10,"") | I14: =IF(ISNUMBER('Lançamento'!D10),'Lançamento'!D10,"") | K14: =IF(ISNUMBER('Lançamento'!E10),'Lançamento'!E10,"") | M14: =IF(ISNUMBER('Lançamento'!F10),'Lançamento'!F10,"") | O14: =IF(ISNUMBER('Lançamento'!G10),'Lançamento'!G10,"") | Q14: =IF(ISNUMBER('Lançamento'!H10),'Lançamento'!H10,"") | S14: =IF(ISNUMBER('Lançamento'!I10),'Lançamento'!I10,"") | U14: =IF(ISNUMBER('Lançamento'!J10),'Lançamento'!J10,"") | W14: =IF(ISNUMBER('Lançamento'!K10),'Lançamento'!K10,"") | Y14: =IF(ISNUMBER('Lançamento'!L10),'Lançamento'!L10,"") | AA14: =IF(ISNUMBER('Lançamento'!M10),'Lançamento'!M10,"") | AC14: =IF(ISNUMBER('Lançamento'!O10),'Lançamento'!O10,"")
A15: =IF('Lançamento'!A11="","",'Lançamento'!A11) | E15: =IF(ISNUMBER('Lançamento'!B11),'Lançamento'!B11,"") | G15: =IF(ISNUMBER('Lançamento'!C11),'Lançamento'!C11,"") | I15: =IF(ISNUMBER('Lançamento'!D11),'Lançamento'!D11,"") | K15: =IF(ISNUMBER('Lançamento'!E11),'Lançamento'!E11,"") | M15: =IF(ISNUMBER('Lançamento'!F11),'Lançamento'!F11,"") | O15: =IF(ISNUMBER('Lançamento'!G11),'Lançamento'!G11,"") | Q15: =IF(ISNUMBER('Lançamento'!H11),'Lançamento'!H11,"") | S15: =IF(ISNUMBER('Lançamento'!I11),'Lançamento'!I11,"") | U15: =IF(ISNUMBER('Lançamento'!J11),'Lançamento'!J11,"") | W15: =IF(ISNUMBER('Lançamento'!K11),'Lançamento'!K11,"") | Y15: =IF(ISNUMBER('Lançamento'!L11),'Lançamento'!L11,"") | AA15: =IF(ISNUMBER('Lançamento'!M11),'Lançamento'!M11,"") | AC15: =IF(ISNUMBER('Lançamento'!O11),'Lançamento'!O11,"")
A16: =IF('Lançamento'!A12="","",'Lançamento'!A12) | E16: =IF(ISNUMBER('Lançamento'!B12),'Lançamento'!B12,"") | G16: =IF(ISNUMBER('Lançamento'!C12),'Lançamento'!C12,"") | I16: =IF(ISNUMBER('Lançamento'!D12),'Lançamento'!D12,"") | K16: =IF(ISNUMBER('Lançamento'!E12),'Lançamento'!E12,"") | M16: =IF(ISNUMBER('Lançamento'!F12),'Lançamento'!F12,"") | O16: =IF(ISNUMBER('Lançamento'!G12),'Lançamento'!G12,"") | Q16: =IF(ISNUMBER('Lançamento'!H12),'Lançamento'!H12,"") | S16: =IF(ISNUMBER('Lançamento'!I12),'Lançamento'!I12,"") | U16: =IF(ISNUMBER('Lançamento'!J12),'Lançamento'!J12,"") | W16: =IF(ISNUMBER('Lançamento'!K12),'Lançamento'!K12,"") | Y16: =IF(ISNUMBER('Lançamento'!L12),'Lançamento'!L12,"") | AA16: =IF(ISNUMBER('Lançamento'!M12),'Lançamento'!M12,"") | AC16: =IF(ISNUMBER('Lançamento'!O12),'Lançamento'!O12,"")
A17: =IF('Lançamento'!A13="","",'Lançamento'!A13) | E17: =IF(ISNUMBER('Lançamento'!B13),'Lançamento'!B13,"") | G17: =IF(ISNUMBER('Lançamento'!C13),'Lançamento'!C13,"") | I17: =IF(ISNUMBER('Lançamento'!D13),'Lançamento'!D13,"") | K17: =IF(ISNUMBER('Lançamento'!E13),'Lançamento'!E13,"") | M17: =IF(ISNUMBER('Lançamento'!F13),'Lançamento'!F13,"") | O17: =IF(ISNUMBER('Lançamento'!G13),'Lançamento'!G13,"") | Q17: =IF(ISNUMBER('Lançamento'!H13),'Lançamento'!H13,"") | S17: =IF(ISNUMBER('Lançamento'!I13),'Lançamento'!I13,"") | U17: =IF(ISNUMBER('Lançamento'!J13),'Lançamento'!J13,"") | W17: =IF(ISNUMBER('Lançamento'!K13),'Lançamento'!K13,"") | Y17: =IF(ISNUMBER('Lançamento'!L13),'Lançamento'!L13,"") | AA17: =IF(ISNUMBER('Lançamento'!M13),'Lançamento'!M13,"") | AC17: =IF(ISNUMBER('Lançamento'!O13),'Lançamento'!O13,"")
A18: =IF('Lançamento'!A14="","",'Lançamento'!A14) | E18: =IF(ISNUMBER('Lançamento'!B14),'Lançamento'!B14,"") | G18: =IF(ISNUMBER('Lançamento'!C14),'Lançamento'!C14,"") | I18: =IF(ISNUMBER('Lançamento'!D14),'Lançamento'!D14,"") | K18: =IF(ISNUMBER('Lançamento'!E14),'Lançamento'!E14,"") | M18: =IF(ISNUMBER('Lançamento'!F14),'Lançamento'!F14,"") | O18: =IF(ISNUMBER('Lançamento'!G14),'Lançamento'!G14,"") | Q18: =IF(ISNUMBER('Lançamento'!H14),'Lançamento'!H14,"") | S18: =IF(ISNUMBER('Lançamento'!I14),'Lançamento'!I14,"") | U18: =IF(ISNUMBER('Lançamento'!J14),'Lançamento'!J14,"") | W18: =IF(ISNUMBER('Lançamento'!K14),'Lançamento'!K14,"") | Y18: =IF(ISNUMBER('Lançamento'!L14),'Lançamento'!L14,"") | AA18: =IF(ISNUMBER('Lançamento'!M14),'Lançamento'!M14,"") | AC18: =IF(ISNUMBER('Lançamento'!O14),'Lançamento'!O14,"")
A19: =IF('Lançamento'!A15="","",'Lançamento'!A15) | E19: =IF(ISNUMBER('Lançamento'!B15),'Lançamento'!B15,"") | G19: =IF(ISNUMBER('Lançamento'!C15),'Lançamento'!C15,"") | I19: =IF(ISNUMBER('Lançamento'!D15),'Lançamento'!D15,"") | K19: =IF(ISNUMBER('Lançamento'!E15),'Lançamento'!E15,"") | M19: =IF(ISNUMBER('Lançamento'!F15),'Lançamento'!F15,"") | O19: =IF(ISNUMBER('Lançamento'!G15),'Lançamento'!G15,"") | Q19: =IF(ISNUMBER('Lançamento'!H15),'Lançamento'!H15,"") | S19: =IF(ISNUMBER('Lançamento'!I15),'Lançamento'!I15,"") | U19: =IF(ISNUMBER('Lançamento'!J15),'Lançamento'!J15,"") | W19: =IF(ISNUMBER('Lançamento'!K15),'Lançamento'!K15,"") | Y19: =IF(ISNUMBER('Lançamento'!L15),'Lançamento'!L15,"") | AA19: =IF(ISNUMBER('Lançamento'!M15),'Lançamento'!M15,"") | AC19: =IF(ISNUMBER('Lançamento'!O15),'Lançamento'!O15,"")
A20: =IF('Lançamento'!A16="","",'Lançamento'!A16) | E20: =IF(ISNUMBER('Lançamento'!B16),'Lançamento'!B16,"") | G20: =IF(ISNUMBER('Lançamento'!C16),'Lançamento'!C16,"") | I20: =IF(ISNUMBER('Lançamento'!D16),'Lançamento'!D16,"") | K20: =IF(ISNUMBER('Lançamento'!E16),'Lançamento'!E16,"") | M20: =IF(ISNUMBER('Lançamento'!F16),'Lançamento'!F16,"") | O20: =IF(ISNUMBER('Lançamento'!G16),'Lançamento'!G16,"") | Q20: =IF(ISNUMBER('Lançamento'!H16),'Lançamento'!H16,"") | S20: =IF(ISNUMBER('Lançamento'!I16),'Lançamento'!I16,"") | U20: =IF(ISNUMBER('Lançamento'!J16),'Lançamento'!J16,"") | W20: =IF(ISNUMBER('Lançamento'!K16),'Lançamento'!K16,"") | Y20: =IF(ISNUMBER('Lançamento'!L16),'Lançamento'!L16,"") | AA20: =IF(ISNUMBER('Lançamento'!M16),'Lançamento'!M16,"") | AC20: =IF(ISNUMBER('Lançamento'!O16),'Lançamento'!O16,"")
A21: =IF('Lançamento'!A17="","",'Lançamento'!A17) | E21: =IF(ISNUMBER('Lançamento'!B17),'Lançamento'!B17,"") | G21: =IF(ISNUMBER('Lançamento'!C17),'Lançamento'!C17,"") | I21: =IF(ISNUMBER('Lançamento'!D17),'Lançamento'!D17,"") | K21: =IF(ISNUMBER('Lançamento'!E17),'Lançamento'!E17,"") | M21: =IF(ISNUMBER('Lançamento'!F17),'Lançamento'!F17,"") | O21: =IF(ISNUMBER('Lançamento'!G17),'Lançamento'!G17,"") | Q21: =IF(ISNUMBER('Lançamento'!H17),'Lançamento'!H17,"") | S21: =IF(ISNUMBER('Lançamento'!I17),'Lançamento'!I17,"") | U21: =IF(ISNUMBER('Lançamento'!J17),'Lançamento'!J17,"") | W21: =IF(ISNUMBER('Lançamento'!K17),'Lançamento'!K17,"") | Y21: =IF(ISNUMBER('Lançamento'!L17),'Lançamento'!L17,"") | AA21: =IF(ISNUMBER('Lançamento'!M17),'Lançamento'!M17,"") | AC21: =IF(ISNUMBER('Lançamento'!O17),'Lançamento'!O17,"")
... A25: =IF('Lançamento'!A21="","",'Lançamento'!A21) | E25: =IF(ISNUMBER('Lançamento'!B21),'Lançamento'!B21,"") | G25: =IF(ISNUMBER('Lançamento'!C21),'Lançamento'!C21,"") | I25: =IF(ISNUMBER('Lançamento'!D21),'Lançamento'!D21,"") | K25: =IF(ISNUMBER('Lançamento'!E21),'Lançamento'!E21,"") | M25: =IF(ISNUMBER('Lançamento'!F21),'Lançamento'!F21,"") | O25: =IF(ISNUMBER('Lançamento'!G21),'Lançamento'!G21,"") | Q25: =IF(ISNUMBER('Lançamento'!H21),'Lançamento'!H21,"") | S25: =IF(ISNUMBER('Lançamento'!I21),'Lançamento'!I21,"") | U25: =IF(ISNUMBER('Lançamento'!J21),'Lançamento'!J21,"") | W25: =IF(ISNUMBER('Lançamento'!K21),'Lançamento'!K21,"") | Y25: =IF(ISNUMBER('Lançamento'!L21),'Lançamento'!L21,"") | AA25: =IF(ISNUMBER('Lançamento'!M21),'Lançamento'!M21,"") | AC25: =IF(ISNUMBER('Lançamento'!O21),'Lançamento'!O21,"")
B27: ="Verde: ≥ "&ROUND('Lançamento'!H3*100,1)&"%" | H27: ="Laranja: ≥ "&ROUND('Lançamento'!K3*100,1)&"% e < "&ROUND('Lançamento'!H3*100,1)&"%" | O27: ="Vermelho: < "&ROUND('Lançamento'!K3*100,1)&"%" | T27: - - - | U27: Meta (linha tracejada) | Z27: —— | AA27: Tendência: média móvel de 3 meses

Sheet Evidências
A1: EVIDÊNCIAS DAS TAXAS DE ATENDIMENTO
A3: Como usar: copie o print (Win+Shift+S), vá em Lançamento, clique na célula do mês e use o botão 'Colar evidência'. Depois digite na coluna E o valor que aparece no print. Colunas cinza são calculadas.
A5: MONTADORA | B5: MÊS Nº | C5: MÊS | D5: TAXA LANÇADA | E5: VALOR NO PRINT | F5: CONFERÊNCIA | G5: ORIGEM | H5: COLADO POR | I5: DATA/HORA | J5: EVIDÊNCIA (PRINT)
C6: =IF($A6="","",CHOOSE($B6,"JAN","FEV","MAR","ABR","MAI","JUN","JUL","AGO","SET","OUT","NOV","DEZ")) | D6: =IF($A6="","",IFERROR(IF(INDEX('Lançamento'!$B$6:$M$35,MATCH($A6,'Lançamento'!$A$6:$A$35,0),$B6)="","",INDEX('Lançamento'!$B$6:$M$35,MATCH($A6,'Lançamento'!$A$6:$A$35,0),$B6)),"")) | F6: =IF($A6="","",IF(OR($D6="",$E6=""),"Digitar valor do print",IF(ABS($D6-$E6)<=0.001,"✔ Confere","⚠ Divergente")))
C7: =IF($A7="","",CHOOSE($B7,"JAN","FEV","MAR","ABR","MAI","JUN","JUL","AGO","SET","OUT","NOV","DEZ")) | D7: =IF($A7="","",IFERROR(IF(INDEX('Lançamento'!$B$6:$M$35,MATCH($A7,'Lançamento'!$A$6:$A$35,0),$B7)="","",INDEX('Lançamento'!$B$6:$M$35,MATCH($A7,'Lançamento'!$A$6:$A$35,0),$B7)),"")) | F7: =IF($A7="","",IF(OR($D7="",$E7=""),"Digitar valor do print",IF(ABS($D7-$E7)<=0.001,"✔ Confere","⚠ Divergente")))
C8: =IF($A8="","",CHOOSE($B8,"JAN","FEV","MAR","ABR","MAI","JUN","JUL","AGO","SET","OUT","NOV","DEZ")) | D8: =IF($A8="","",IFERROR(IF(INDEX('Lançamento'!$B$6:$M$35,MATCH($A8,'Lançamento'!$A$6:$A$35,0),$B8)="","",INDEX('Lançamento'!$B$6:$M$35,MATCH($A8,'Lançamento'!$A$6:$A$35,0),$B8)),"")) | F8: =IF($A8="","",IF(OR($D8="",$E8=""),"Digitar valor do print",IF(ABS($D8-$E8)<=0.001,"✔ Confere","⚠ Divergente")))
C9: =IF($A9="","",CHOOSE($B9,"JAN","FEV","MAR","ABR","MAI","JUN","JUL","AGO","SET","OUT","NOV","DEZ")) | D9: =IF($A9="","",IFERROR(IF(INDEX('Lançamento'!$B$6:$M$35,MATCH($A9,'Lançamento'!$A$6:$A$35,0),$B9)="","",INDEX('Lançamento'!$B$6:$M$35,MATCH($A9,'Lançamento'!$A$6:$A$35,0),$B9)),"")) | F9: =IF($A9="","",IF(OR($D9="",$E9=""),"Digitar valor do print",IF(ABS($D9-$E9)<=0.001,"✔ Confere","⚠ Divergente")))
C10: =IF($A10="","",CHOOSE($B10,"JAN","FEV","MAR","ABR","MAI","JUN","JUL","AGO","SET","OUT","NOV","DEZ")) | D10: =IF($A10="","",IFERROR(IF(INDEX('Lançamento'!$B$6:$M$35,MATCH($A10,'Lançamento'!$A$6:$A$35,0),$B10)="","",INDEX('Lançamento'!$B$6:$M$35,MATCH($A10,'Lançamento'!$A$6:$A$35,0),$B10)),"")) | F10: =IF($A10="","",IF(OR($D10="",$E10=""),"Digitar valor do print",IF(ABS($D10-$E10)<=0.001,"✔ Confere","⚠ Divergente")))
C11: =IF($A11="","",CHOOSE($B11,"JAN","FEV","MAR","ABR","MAI","JUN","JUL","AGO","SET","OUT","NOV","DEZ")) | D11: =IF($A11="","",IFERROR(IF(INDEX('Lançamento'!$B$6:$M$35,MATCH($A11,'Lançamento'!$A$6:$A$35,0),$B11)="","",INDEX('Lançamento'!$B$6:$M$35,MATCH($A11,'Lançamento'!$A$6:$A$35,0),$B11)),"")) | F11: =IF($A11="","",IF(OR($D11="",$E11=""),"Digitar valor do print",IF(ABS($D11-$E11)<=0.001,"✔ Confere","⚠ Divergente")))
C12: =IF($A12="","",CHOOSE($B12,"JAN","FEV","MAR","ABR","MAI","JUN","JUL","AGO","SET","OUT","NOV","DEZ")) | D12: =IF($A12="","",IFERROR(IF(INDEX('Lançamento'!$B$6:$M$35,MATCH($A12,'Lançamento'!$A$6:$A$35,0),$B12)="","",INDEX('Lançamento'!$B$6:$M$35,MATCH($A12,'Lançamento'!$A$6:$A$35,0),$B12)),"")) | F12: =IF($A12="","",IF(OR($D12="",$E12=""),"Digitar valor do print",IF(ABS($D12-$E12)<=0.001,"✔ Confere","⚠ Divergente")))
C13: =IF($A13="","",CHOOSE($B13,"JAN","FEV","MAR","ABR","MAI","JUN","JUL","AGO","SET","OUT","NOV","DEZ")) | D13: =IF($A13="","",IFERROR(IF(INDEX('Lançamento'!$B$6:$M$35,MATCH($A13,'Lançamento'!$A$6:$A$35,0),$B13)="","",INDEX('Lançamento'!$B$6:$M$35,MATCH($A13,'Lançamento'!$A$6:$A$35,0),$B13)),"")) | F13: =IF($A13="","",IF(OR($D13="",$E13=""),"Digitar valor do print",IF(ABS($D13-$E13)<=0.001,"✔ Confere","⚠ Divergente")))
C14: =IF($A14="","",CHOOSE($B14,"JAN","FEV","MAR","ABR","MAI","JUN","JUL","AGO","SET","OUT","NOV","DEZ")) | D14: =IF($A14="","",IFERROR(IF(INDEX('Lançamento'!$B$6:$M$35,MATCH($A14,'Lançamento'!$A$6:$A$35,0),$B14)="","",INDEX('Lançamento'!$B$6:$M$35,MATCH($A14,'Lançamento'!$A$6:$A$35,0),$B14)),"")) | F14: =IF($A14="","",IF(OR($D14="",$E14=""),"Digitar valor do print",IF(ABS($D14-$E14)<=0.001,"✔ Confere","⚠ Divergente")))
C15: =IF($A15="","",CHOOSE($B15,"JAN","FEV","MAR","ABR","MAI","JUN","JUL","AGO","SET","OUT","NOV","DEZ")) | D15: =IF($A15="","",IFERROR(IF(INDEX('Lançamento'!$B$6:$M$35,MATCH($A15,'Lançamento'!$A$6:$A$35,0),$B15)="","",INDEX('Lançamento'!$B$6:$M$35,MATCH($A15,'Lançamento'!$A$6:$A$35,0),$B15)),"")) | F15: =IF($A15="","",IF(OR($D15="",$E15=""),"Digitar valor do print",IF(ABS($D15-$E15)<=0.001,"✔ Confere","⚠ Divergente")))
C16: =IF($A16="","",CHOOSE($B16,"JAN","FEV","MAR","ABR","MAI","JUN","JUL","AGO","SET","OUT","NOV","DEZ")) | D16: =IF($A16="","",IFERROR(IF(INDEX('Lançamento'!$B$6:$M$35,MATCH($A16,'Lançamento'!$A$6:$A$35,0),$B16)="","",INDEX('Lançamento'!$B$6:$M$35,MATCH($A16,'Lançamento'!$A$6:$A$35,0),$B16)),"")) | F16: =IF($A16="","",IF(OR($D16="",$E16=""),"Digitar valor do print",IF(ABS($D16-$E16)<=0.001,"✔ Confere","⚠ Divergente")))
C17: =IF($A17="","",CHOOSE($B17,"JAN","FEV","MAR","ABR","MAI","JUN","JUL","AGO","SET","OUT","NOV","DEZ")) | D17: =IF($A17="","",IFERROR(IF(INDEX('Lançamento'!$B$6:$M$35,MATCH($A17,'Lançamento'!$A$6:$A$35,0),$B17)="","",INDEX('Lançamento'!$B$6:$M$35,MATCH($A17,'Lançamento'!$A$6:$A$35,0),$B17)),"")) | F17: =IF($A17="","",IF(OR($D17="",$E17=""),"Digitar valor do print",IF(ABS($D17-$E17)<=0.001,"✔ Confere","⚠ Divergente")))
... C405: =IF($A405="","",CHOOSE($B405,"JAN","FEV","MAR","ABR","MAI","JUN","JUL","AGO","SET","OUT","NOV","DEZ")) | D405: =IF($A405="","",IFERROR(IF(INDEX('Lançamento'!$B$6:$M$35,MATCH($A405,'Lançamento'!$A$6:$A$35,0),$B405)="","",INDEX('Lançamento'!$B$6:$M$35,MATCH($A405,'Lançamento'!$A$6:$A$35,0),$B405)),"")) | F405: =IF($A405="","",IF(OR($D405="",$E405=""),"Digitar valor do print",IF(ABS($D405-$E405)<=0.001,"✔ Confere","⚠ Divergente")))

Sheet Aux
A1: Aba auxiliar (oculta): alimenta os gráficos e o resumo. Não editar.
A2: Último mês com lançamento | B2: =SUMPRODUCT(MAX(('Lançamento'!B6:M35<>"")*(COLUMN('Lançamento'!B6:M35)-1)))
A3: Montadoras no verde no último mês | B3: =IF(B2=0,0,SUMPRODUCT(ISNUMBER(INDEX('Lançamento'!B6:M35,0,B2))*(ROUND(INDEX('Lançamento'!B6:M35,0,B2),6)>=ROUND('Lançamento'!$H$3,6))))
A4: Montadoras com valor no último mês | B4: =IF(B2=0,0,SUMPRODUCT(--ISNUMBER(INDEX('Lançamento'!B6:M35,0,B2))))
A5: Montadora | B5: VERDE_JAN | C5: VERDE_FEV | D5: VERDE_MAR | E5: VERDE_ABR | F5: VERDE_MAI | G5: VERDE_JUN | H5: VERDE_JUL | I5: VERDE_AGO | J5: VERDE_SET | K5: VERDE_OUT | L5: VERDE_NOV | M5: VERDE_DEZ | N5: LARANJA_JAN | O5: LARANJA_FEV | P5: LARANJA_MAR | Q5: LARANJA_ABR | R5: LARANJA_MAI | S5: LARANJA_JUN | T5: LARANJA_JUL | U5: LARANJA_AGO | V5: LARANJA_SET | W5: LARANJA_OUT | X5: LARANJA_NOV | Y5: LARANJA_DEZ | Z5: VERMELHO_JAN | AA5: VERMELHO_FEV | AB5: VERMELHO_MAR | AC5: VERMELHO_ABR | AD5: VERMELHO_MAI | AE5: VERMELHO_JUN | AF5: VERMELHO_JUL | AG5: VERMELHO_AGO | AH5: VERMELHO_SET | AI5: VERMELHO_OUT | AJ5: VERMELHO_NOV | AK5: VERMELHO_DEZ | AL5: META_JAN | AM5: META_FEV | AN5: META_MAR | AO5: META_ABR | AP5: META_MAI | AQ5: META_JUN | AR5: META_JUL | AS5: META_AGO | AT5: META_SET | AU5: META_OUT | AV5: META_NOV | AW5: META_DEZ | AX5: TENDENCIA_JAN | AY5: TENDENCIA_FEV | AZ5: TENDENCIA_MAR | BA5: TENDENCIA_ABR | BB5: TENDENCIA_MAI | BC5: TENDENCIA_JUN | BD5: TENDENCIA_JUL | BE5: TENDENCIA_AGO | BF5: TENDENCIA_SET | BG5: TENDENCIA_OUT | BH5: TENDENCIA_NOV | BI5: TENDENCIA_DEZ | BJ5: TITULO
A6: =IF('Lançamento'!A6="","",'Lançamento'!A6) | B6: =IF(AND(ISNUMBER('Lançamento'!B6),ROUND('Lançamento'!B6,6)>=ROUND('Lançamento'!$H$3,6)),'Lançamento'!B6,0) | C6: =IF(AND(ISNUMBER('Lançamento'!C6),ROUND('Lançamento'!C6,6)>=ROUND('Lançamento'!$H$3,6)),'Lançamento'!C6,0) | D6: =IF(AND(ISNUMBER('Lançamento'!D6),ROUND('Lançamento'!D6,6)>=ROUND('Lançamento'!$H$3,6)),'Lançamento'!D6,0) | E6: =IF(AND(ISNUMBER('Lançamento'!E6),ROUND('Lançamento'!E6,6)>=ROUND('Lançamento'!$H$3,6)),'Lançamento'!E6,0) | F6: =IF(AND(ISNUMBER('Lançamento'!F6),ROUND('Lançamento'!F6,6)>=ROUND('Lançamento'!$H$3,6)),'Lançamento'!F6,0) | G6: =IF(AND(ISNUMBER('Lançamento'!G6),ROUND('Lançamento'!G6,6)>=ROUND('Lançamento'!$H$3,6)),'Lançamento'!G6,0) | H6: =IF(AND(ISNUMBER('Lançamento'!H6),ROUND('Lançamento'!H6,6)>=ROUND('Lançamento'!$H$3,6)),'Lançamento'!H6,0) | I6: =IF(AND(ISNUMBER('Lançamento'!I6),ROUND('Lançamento'!I6,6)>=ROUND('Lançamento'!$H$3,6)),'Lançamento'!I6,0) | ... M6: =IF(AND(ISNUMBER('Lançamento'!M6),ROUND('Lançamento'!M6,6)>=ROUND('Lançamento'!$H$3,6)),'Lançamento'!M6,0) | N6: =IF(AND(ISNUMBER('Lançamento'!B6),ROUND('Lançamento'!B6,6)<ROUND('Lançamento'!$H$3,6),ROUND('Lançamento'!B6,6)>=ROUND('Lançamento'!$K$3,6)),'Lançamento'!B6,0) | O6: =IF(AND(ISNUMBER('Lançamento'!C6),ROUND('Lançamento'!C6,6)<ROUND('Lançamento'!$H$3,6),ROUND('Lançamento'!C6,6)>=ROUND('Lançamento'!$K$3,6)),'Lançamento'!C6,0) | P6: =IF(AND(ISNUMBER('Lançamento'!D6),ROUND('Lançamento'!D6,6)<ROUND('Lançamento'!$H$3,6),ROUND('Lançamento'!D6,6)>=ROUND('Lançamento'!$K$3,6)),'Lançamento'!D6,0) | Q6: =IF(AND(ISNUMBER('Lançamento'!E6),ROUND('Lançamento'!E6,6)<ROUND('Lançamento'!$H$3,6),ROUND('Lançamento'!E6,6)>=ROUND('Lançamento'!$K$3,6)),'Lançamento'!E6,0) | R6: =IF(AND(ISNUMBER('Lançamento'!F6),ROUND('Lançamento'!F6,6)<ROUND('Lançamento'!$H$3,6),ROUND('Lançamento'!F6,6)>=ROUND('Lançamento'!$K$3,6)),'Lançamento'!F6,0) | S6: =IF(AND(ISNUMBER('Lançamento'!G6),ROUND('Lançamento'!G6,6)<ROUND('Lançamento'!$H$3,6),ROUND('Lançamento'!G6,6)>=ROUND('Lançamento'!$K$3,6)),'Lançamento'!G6,0) | T6: =IF(AND(ISNUMBER('Lançamento'!H6),ROUND('Lançamento'!H6,6)<ROUND('Lançamento'!$H$3,6),ROUND('Lançamento'!H6,6)>=ROUND('Lançamento'!$K$3,6)),'Lançamento'!H6,0) | U6: =IF(AND(ISNUMBER('Lançamento'!I6),ROUND('Lançamento'!I6,6)<ROUND('Lançamento'!$H$3,6),ROUND('Lançamento'!I6,6)>=ROUND('Lançamento'!$K$3,6)),'Lançamento'!I6,0) | ... Y6: =IF(AND(ISNUMBER('Lançamento'!M6),ROUND('Lançamento'!M6,6)<ROUND('Lançamento'!$H$3,6),ROUND('Lançamento'!M6,6)>=ROUND('Lançamento'!$K$3,6)),'Lançamento'!M6,0) | Z6: =IF(AND(ISNUMBER('Lançamento'!B6),ROUND('Lançamento'!B6,6)<ROUND('Lançamento'!$K$3,6)),'Lançamento'!B6,0) | AA6: =IF(AND(ISNUMBER('Lançamento'!C6),ROUND('Lançamento'!C6,6)<ROUND('Lançamento'!$K$3,6)),'Lançamento'!C6,0) | AB6: =IF(AND(ISNUMBER('Lançamento'!D6),ROUND('Lançamento'!D6,6)<ROUND('Lançamento'!$K$3,6)),'Lançamento'!D6,0) | AC6: =IF(AND(ISNUMBER('Lançamento'!E6),ROUND('Lançamento'!E6,6)<ROUND('Lançamento'!$K$3,6)),'Lançamento'!E6,0) | AD6: =IF(AND(ISNUMBER('Lançamento'!F6),ROUND('Lançamento'!F6,6)<ROUND('Lançamento'!$K$3,6)),'Lançamento'!F6,0) | AE6: =IF(AND(ISNUMBER('Lançamento'!G6),ROUND('Lançamento'!G6,6)<ROUND('Lançamento'!$K$3,6)),'Lançamento'!G6,0) | AF6: =IF(AND(ISNUMBER('Lançamento'!H6),ROUND('Lançamento'!H6,6)<ROUND('Lançamento'!$K$3,6)),'Lançamento'!H6,0) | AG6: =IF(AND(ISNUMBER('Lançamento'!I6),ROUND('Lançamento'!I6,6)<ROUND('Lançamento'!$K$3,6)),'Lançamento'!I6,0) | ... AK6: =IF(AND(ISNUMBER('Lançamento'!M6),ROUND('Lançamento'!M6,6)<ROUND('Lançamento'!$K$3,6)),'Lançamento'!M6,0) | AL6: =IF(ISNUMBER('Lançamento'!$N6),'Lançamento'!$N6,0) | AM6: =IF(ISNUMBER('Lançamento'!$N6),'Lançamento'!$N6,0) | AN6: =IF(ISNUMBER('Lançamento'!$N6),'Lançamento'!$N6,0) | AO6: =IF(ISNUMBER('Lançamento'!$N6),'Lançamento'!$N6,0) | AP6: =IF(ISNUMBER('Lançamento'!$N6),'Lançamento'!$N6,0) | AQ6: =IF(ISNUMBER('Lançamento'!$N6),'Lançamento'!$N6,0) | AR6: =IF(ISNUMBER('Lançamento'!$N6),'Lançamento'!$N6,0) | AS6: =IF(ISNUMBER('Lançamento'!$N6),'Lançamento'!$N6,0) | ... AW6: =IF(ISNUMBER('Lançamento'!$N6),'Lançamento'!$N6,0) | AX6: =NA() | AY6: =NA() | AZ6: =IF(COUNT('Lançamento'!B6:'Lançamento'!D6)=3,AVERAGE('Lançamento'!B6:'Lançamento'!D6),NA()) | BA6: =IF(COUNT('Lançamento'!C6:'Lançamento'!E6)=3,AVERAGE('Lançamento'!C6:'Lançamento'!E6),NA()) | BB6: =IF(COUNT('Lançamento'!D6:'Lançamento'!F6)=3,AVERAGE('Lançamento'!D6:'Lançamento'!F6),NA()) | BC6: =IF(COUNT('Lançamento'!E6:'Lançamento'!G6)=3,AVERAGE('Lançamento'!E6:'Lançamento'!G6),NA()) | BD6: =IF(COUNT('Lançamento'!F6:'Lançamento'!H6)=3,AVERAGE('Lançamento'!F6:'Lançamento'!H6),NA()) | BE6: =IF(COUNT('Lançamento'!G6:'Lançamento'!I6)=3,AVERAGE('Lançamento'!G6:'Lançamento'!I6),NA()) | BF6: =IF(COUNT('Lançamento'!H6:'Lançamento'!J6)=3,AVERAGE('Lançamento'!H6:'Lançamento'!J6),NA()) | BG6: =IF(COUNT('Lançamento'!I6:'Lançamento'!K6)=3,AVERAGE('Lançamento'!I6:'Lançamento'!K6),NA()) | ... BI6: =IF(COUNT('Lançamento'!K6:'Lançamento'!M6)=3,AVERAGE('Lançamento'!K6:'Lançamento'!M6),NA()) | BJ6: =IF('Lançamento'!A6="","",'Lançamento'!A6&" | Média YTD: "&IF('Lançamento'!O6="","-",ROUND('Lançamento'!O6*100,1)&"%"))
A7: =IF('Lançamento'!A7="","",'Lançamento'!A7) | B7: =IF(AND(ISNUMBER('Lançamento'!B7),ROUND('Lançamento'!B7,6)>=ROUND('Lançamento'!$H$3,6)),'Lançamento'!B7,0) | C7: =IF(AND(ISNUMBER('Lançamento'!C7),ROUND('Lançamento'!C7,6)>=ROUND('Lançamento'!$H$3,6)),'Lançamento'!C7,0) | D7: =IF(AND(ISNUMBER('Lançamento'!D7),ROUND('Lançamento'!D7,6)>=ROUND('Lançamento'!$H$3,6)),'Lançamento'!D7,0) | E7: =IF(AND(ISNUMBER('Lançamento'!E7),ROUND('Lançamento'!E7,6)>=ROUND('Lançamento'!$H$3,6)),'Lançamento'!E7,0) | F7: =IF(AND(ISNUMBER('Lançamento'!F7),ROUND('Lançamento'!F7,6)>=ROUND('Lançamento'!$H$3,6)),'Lançamento'!F7,0) | G7: =IF(AND(ISNUMBER('Lançamento'!G7),ROUND('Lançamento'!G7,6)>=ROUND('Lançamento'!$H$3,6)),'Lançamento'!G7,0) | H7: =IF(AND(ISNUMBER('Lançamento'!H7),ROUND('Lançamento'!H7,6)>=ROUND('Lançamento'!$H$3,6)),'Lançamento'!H7,0) | I7: =IF(AND(ISNUMBER('Lançamento'!I7),ROUND('Lançamento'!I7,6)>=ROUND('Lançamento'!$H$3,6)),'Lançamento'!I7,0) | ... M7: =IF(AND(ISNUMBER('Lançamento'!M7),ROUND('Lançamento'!M7,6)>=ROUND('Lançamento'!$H$3,6)),'Lançamento'!M7,0) | N7: =IF(AND(ISNUMBER('Lançamento'!B7),ROUND('Lançamento'!B7,6)<ROUND('Lançamento'!$H$3,6),ROUND('Lançamento'!B7,6)>=ROUND('Lançamento'!$K$3,6)),'Lançamento'!B7,0) | O7: =IF(AND(ISNUMBER('Lançamento'!C7),ROUND('Lançamento'!C7,6)<ROUND('Lançamento'!$H$3,6),ROUND('Lançamento'!C7,6)>=ROUND('Lançamento'!$K$3,6)),'Lançamento'!C7,0) | P7: =IF(AND(ISNUMBER('Lançamento'!D7),ROUND('Lançamento'!D7,6)<ROUND('Lançamento'!$H$3,6),ROUND('Lançamento'!D7,6)>=ROUND('Lançamento'!$K$3,6)),'Lançamento'!D7,0) | Q7: =IF(AND(ISNUMBER('Lançamento'!E7),ROUND('Lançamento'!E7,6)<ROUND('Lançamento'!$H$3,6),ROUND('Lançamento'!E7,6)>=ROUND('Lançamento'!$K$3,6)),'Lançamento'!E7,0) | R7: =IF(AND(ISNUMBER('Lançamento'!F7),ROUND('Lançamento'!F7,6)<ROUND('Lançamento'!$H$3,6),ROUND('Lançamento'!F7,6)>=ROUND('Lançamento'!$K$3,6)),'Lançamento'!F7,0) | S7: =IF(AND(ISNUMBER('Lançamento'!G7),ROUND('Lançamento'!G7,6)<ROUND('Lançamento'!$H$3,6),ROUND('Lançamento'!G7,6)>=ROUND('Lançamento'!$K$3,6)),'Lançamento'!G7,0) | T7: =IF(AND(ISNUMBER('Lançamento'!H7),ROUND('Lançamento'!H7,6)<ROUND('Lançamento'!$H$3,6),ROUND('Lançamento'!H7,6)>=ROUND('Lançamento'!$K$3,6)),'Lançamento'!H7,0) | U7: =IF(AND(ISNUMBER('Lançamento'!I7),ROUND('Lançamento'!I7,6)<ROUND('Lançamento'!$H$3,6),ROUND('Lançamento'!I7,6)>=ROUND('Lançamento'!$K$3,6)),'Lançamento'!I7,0) | ... Y7: =IF(AND(ISNUMBER('Lançamento'!M7),ROUND('Lançamento'!M7,6)<ROUND('Lançamento'!$H$3,6),ROUND('Lançamento'!M7,6)>=ROUND('Lançamento'!$K$3,6)),'Lançamento'!M7,0) | Z7: =IF(AND(ISNUMBER('Lançamento'!B7),ROUND('Lançamento'!B7,6)<ROUND('Lançamento'!$K$3,6)),'Lançamento'!B7,0) | AA7: =IF(AND(ISNUMBER('Lançamento'!C7),ROUND('Lançamento'!C7,6)<ROUND('Lançamento'!$K$3,6)),'Lançamento'!C7,0) | AB7: =IF(AND(ISNUMBER('Lançamento'!D7),ROUND('Lançamento'!D7,6)<ROUND('Lançamento'!$K$3,6)),'Lançamento'!D7,0) | AC7: =IF(AND(ISNUMBER('Lançamento'!E7),ROUND('Lançamento'!E7,6)<ROUND('Lançamento'!$K$3,6)),'Lançamento'!E7,0) | AD7: =IF(AND(ISNUMBER('Lançamento'!F7),ROUND('Lançamento'!F7,6)<ROUND('Lançamento'!$K$3,6)),'Lançamento'!F7,0) | AE7: =IF(AND(ISNUMBER('Lançamento'!G7),ROUND('Lançamento'!G7,6)<ROUND('Lançamento'!$K$3,6)),'Lançamento'!G7,0) | AF7: =IF(AND(ISNUMBER('Lançamento'!H7),ROUND('Lançamento'!H7,6)<ROUND('Lançamento'!$K$3,6)),'Lançamento'!H7,0) | AG7: =IF(AND(ISNUMBER('Lançamento'!I7),ROUND('Lançamento'!I7,6)<ROUND('Lançamento'!$K$3,6)),'Lançamento'!I7,0) | ... AK7: =IF(AND(ISNUMBER('Lançamento'!M7),ROUND('Lançamento'!M7,6)<ROUND('Lançamento'!$K$3,6)),'Lançamento'!M7,0) | AL7: =IF(ISNUMBER('Lançamento'!$N7),'Lançamento'!$N7,0) | AM7: =IF(ISNUMBER('Lançamento'!$N7),'Lançamento'!$N7,0) | AN7: =IF(ISNUMBER('Lançamento'!$N7),'Lançamento'!$N7,0) | AO7: =IF(ISNUMBER('Lançamento'!$N7),'Lançamento'!$N7,0) | AP7: =IF(ISNUMBER('Lançamento'!$N7),'Lançamento'!$N7,0) | AQ7: =IF(ISNUMBER('Lançamento'!$N7),'Lançamento'!$N7,0) | AR7: =IF(ISNUMBER('Lançamento'!$N7),'Lançamento'!$N7,0) | AS7: =IF(ISNUMBER('Lançamento'!$N7),'Lançamento'!$N7,0) | ... AW7: =IF(ISNUMBER('Lançamento'!$N7),'Lançamento'!$N7,0) | AX7: =NA() | AY7: =NA() | AZ7: =IF(COUNT('Lançamento'!B7:'Lançamento'!D7)=3,AVERAGE('Lançamento'!B7:'Lançamento'!D7),NA()) | BA7: =IF(COUNT('Lançamento'!C7:'Lançamento'!E7)=3,AVERAGE('Lançamento'!C7:'Lançamento'!E7),NA()) | BB7: =IF(COUNT('Lançamento'!D7:'Lançamento'!F7)=3,AVERAGE('Lançamento'!D7:'Lançamento'!F7),NA()) | BC7: =IF(COUNT('Lançamento'!E7:'Lançamento'!G7)=3,AVERAGE('Lançamento'!E7:'Lançamento'!G7),NA()) | BD7: =IF(COUNT('Lançamento'!F7:'Lançamento'!H7)=3,AVERAGE('Lançamento'!F7:'Lançamento'!H7),NA()) | BE7: =IF(COUNT('Lançamento'!G7:'Lançamento'!I7)=3,AVERAGE('Lançamento'!G7:'Lançamento'!I7),NA()) | BF7: =IF(COUNT('Lançamento'!H7:'Lançamento'!J7)=3,AVERAGE('Lançamento'!H7:'Lançamento'!J7),NA()) | BG7: =IF(COUNT('Lançamento'!I7:'Lançamento'!K7)=3,AVERAGE('Lançamento'!I7:'Lançamento'!K7),NA()) | ... BI7: =IF(COUNT('Lançamento'!K7:'Lançamento'!M7)=3,AVERAGE('Lançamento'!K7:'Lançamento'!M7),NA()) | BJ7: =IF('Lançamento'!A7="","",'Lançamento'!A7&" | Média YTD: "&IF('Lançamento'!O7="","-",ROUND('Lançamento'!O7*100,1)&"%"))
A8: =IF('Lançamento'!A8="","",'Lançamento'!A8) | B8: =IF(AND(ISNUMBER('Lançamento'!B8),ROUND('Lançamento'!B8,6)>=ROUND('Lançamento'!$H$3,6)),'Lançamento'!B8,0) | C8: =IF(AND(ISNUMBER('Lançamento'!C8),ROUND('Lançamento'!C8,6)>=ROUND('Lançamento'!$H$3,6)),'Lançamento'!C8,0) | D8: =IF(AND(ISNUMBER('Lançamento'!D8),ROUND('Lançamento'!D8,6)>=ROUND('Lançamento'!$H$3,6)),'Lançamento'!D8,0) | E8: =IF(AND(ISNUMBER('Lançamento'!E8),ROUND('Lançamento'!E8,6)>=ROUND('Lançamento'!$H$3,6)),'Lançamento'!E8,0) | F8: =IF(AND(ISNUMBER('Lançamento'!F8),ROUND('Lançamento'!F8,6)>=ROUND('Lançamento'!$H$3,6)),'Lançamento'!F8,0) | G8: =IF(AND(ISNUMBER('Lançamento'!G8),ROUND('Lançamento'!G8,6)>=ROUND('Lançamento'!$H$3,6)),'Lançamento'!G8,0) | H8: =IF(AND(ISNUMBER('Lançamento'!H8),ROUND('Lançamento'!H8,6)>=ROUND('Lançamento'!$H$3,6)),'Lançamento'!H8,0) | I8: =IF(AND(ISNUMBER('Lançamento'!I8),ROUND('Lançamento'!I8,6)>=ROUND('Lançamento'!$H$3,6)),'Lançamento'!I8,0) | ... M8: =IF(AND(ISNUMBER('Lançamento'!M8),ROUND('Lançamento'!M8,6)>=ROUND('Lançamento'!$H$3,6)),'Lançamento'!M8,0) | N8: =IF(AND(ISNUMBER('Lançamento'!B8),ROUND('Lançamento'!B8,6)<ROUND('Lançamento'!$H$3,6),ROUND('Lançamento'!B8,6)>=ROUND('Lançamento'!$K$3,6)),'Lançamento'!B8,0) | O8: =IF(AND(ISNUMBER('Lançamento'!C8),ROUND('Lançamento'!C8,6)<ROUND('Lançamento'!$H$3,6),ROUND('Lançamento'!C8,6)>=ROUND('Lançamento'!$K$3,6)),'Lançamento'!C8,0) | P8: =IF(AND(ISNUMBER('Lançamento'!D8),ROUND('Lançamento'!D8,6)<ROUND('Lançamento'!$H$3,6),ROUND('Lançamento'!D8,6)>=ROUND('Lançamento'!$K$3,6)),'Lançamento'!D8,0) | Q8: =IF(AND(ISNUMBER('Lançamento'!E8),ROUND('Lançamento'!E8,6)<ROUND('Lançamento'!$H$3,6),ROUND('Lançamento'!E8,6)>=ROUND('Lançamento'!$K$3,6)),'Lançamento'!E8,0) | R8: =IF(AND(ISNUMBER('Lançamento'!F8),ROUND('Lançamento'!F8,6)<ROUND('Lançamento'!$H$3,6),ROUND('Lançamento'!F8,6)>=ROUND('Lançamento'!$K$3,6)),'Lançamento'!F8,0) | S8: =IF(AND(ISNUMBER('Lançamento'!G8),ROUND('Lançamento'!G8,6)<ROUND('Lançamento'!$H$3,6),ROUND('Lançamento'!G8,6)>=ROUND('Lançamento'!$K$3,6)),'Lançamento'!G8,0) | T8: =IF(AND(ISNUMBER('Lançamento'!H8),ROUND('Lançamento'!H8,6)<ROUND('Lançamento'!$H$3,6),ROUND('Lançamento'!H8,6)>=ROUND('Lançamento'!$K$3,6)),'Lançamento'!H8,0) | U8: =IF(AND(ISNUMBER('Lançamento'!I8),ROUND('Lançamento'!I8,6)<ROUND('Lançamento'!$H$3,6),ROUND('Lançamento'!I8,6)>=ROUND('Lançamento'!$K$3,6)),'Lançamento'!I8,0) | ... Y8: =IF(AND(ISNUMBER('Lançamento'!M8),ROUND('Lançamento'!M8,6)<ROUND('Lançamento'!$H$3,6),ROUND('Lançamento'!M8,6)>=ROUND('Lançamento'!$K$3,6)),'Lançamento'!M8,0) | Z8: =IF(AND(ISNUMBER('Lançamento'!B8),ROUND('Lançamento'!B8,6)<ROUND('Lançamento'!$K$3,6)),'Lançamento'!B8,0) | AA8: =IF(AND(ISNUMBER('Lançamento'!C8),ROUND('Lançamento'!C8,6)<ROUND('Lançamento'!$K$3,6)),'Lançamento'!C8,0) | AB8: =IF(AND(ISNUMBER('Lançamento'!D8),ROUND('Lançamento'!D8,6)<ROUND('Lançamento'!$K$3,6)),'Lançamento'!D8,0) | AC8: =IF(AND(ISNUMBER('Lançamento'!E8),ROUND('Lançamento'!E8,6)<ROUND('Lançamento'!$K$3,6)),'Lançamento'!E8,0) | AD8: =IF(AND(ISNUMBER('Lançamento'!F8),ROUND('Lançamento'!F8,6)<ROUND('Lançamento'!$K$3,6)),'Lançamento'!F8,0) | AE8: =IF(AND(ISNUMBER('Lançamento'!G8),ROUND('Lançamento'!G8,6)<ROUND('Lançamento'!$K$3,6)),'Lançamento'!G8,0) | AF8: =IF(AND(ISNUMBER('Lançamento'!H8),ROUND('Lançamento'!H8,6)<ROUND('Lançamento'!$K$3,6)),'Lançamento'!H8,0) | AG8: =IF(AND(ISNUMBER('Lançamento'!I8),ROUND('Lançamento'!I8,6)<ROUND('Lançamento'!$K$3,6)),'Lançamento'!I8,0) | ... AK8: =IF(AND(ISNUMBER('Lançamento'!M8),ROUND('Lançamento'!M8,6)<ROUND('Lançamento'!$K$3,6)),'Lançamento'!M8,0) | AL8: =IF(ISNUMBER('Lançamento'!$N8),'Lançamento'!$N8,0) | AM8: =IF(ISNUMBER('Lançamento'!$N8),'Lançamento'!$N8,0) | AN8: =IF(ISNUMBER('Lançamento'!$N8),'Lançamento'!$N8,0) | AO8: =IF(ISNUMBER('Lançamento'!$N8),'Lançamento'!$N8,0) | AP8: =IF(ISNUMBER('Lançamento'!$N8),'Lançamento'!$N8,0) | AQ8: =IF(ISNUMBER('Lançamento'!$N8),'Lançamento'!$N8,0) | AR8: =IF(ISNUMBER('Lançamento'!$N8),'Lançamento'!$N8,0) | AS8: =IF(ISNUMBER('Lançamento'!$N8),'Lançamento'!$N8,0) | ... AW8: =IF(ISNUMBER('Lançamento'!$N8),'Lançamento'!$N8,0) | AX8: =NA() | AY8: =NA() | AZ8: =IF(COUNT('Lançamento'!B8:'Lançamento'!D8)=3,AVERAGE('Lançamento'!B8:'Lançamento'!D8),NA()) | BA8: =IF(COUNT('Lançamento'!C8:'Lançamento'!E8)=3,AVERAGE('Lançamento'!C8:'Lançamento'!E8),NA()) | BB8: =IF(COUNT('Lançamento'!D8:'Lançamento'!F8)=3,AVERAGE('Lançamento'!D8:'Lançamento'!F8),NA()) | BC8: =IF(COUNT('Lançamento'!E8:'Lançamento'!G8)=3,AVERAGE('Lançamento'!E8:'Lançamento'!G8),NA()) | BD8: =IF(COUNT('Lançamento'!F8:'Lançamento'!H8)=3,AVERAGE('Lançamento'!F8:'Lançamento'!H8),NA()) | BE8: =IF(COUNT('Lançamento'!G8:'Lançamento'!I8)=3,AVERAGE('Lançamento'!G8:'Lançamento'!I8),NA()) | BF8: =IF(COUNT('Lançamento'!H8:'Lançamento'!J8)=3,AVERAGE('Lançamento'!H8:'Lançamento'!J8),NA()) | BG8: =IF(COUNT('Lançamento'!I8:'Lançamento'!K8)=3,AVERAGE('Lançamento'!I8:'Lançamento'!K8),NA()) | ... BI8: =IF(COUNT('Lançamento'!K8:'Lançamento'!M8)=3,AVERAGE('Lançamento'!K8:'Lançamento'!M8),NA()) | BJ8: =IF('Lançamento'!A8="","",'Lançamento'!A8&" | Média YTD: "&IF('Lançamento'!O8="","-",ROUND('Lançamento'!O8*100,1)&"%"))
A9: =IF('Lançamento'!A9="","",'Lançamento'!A9) | B9: =IF(AND(ISNUMBER('Lançamento'!B9),ROUND('Lançamento'!B9,6)>=ROUND('Lançamento'!$H$3,6)),'Lançamento'!B9,0) | C9: =IF(AND(ISNUMBER('Lançamento'!C9),ROUND('Lançamento'!C9,6)>=ROUND('Lançamento'!$H$3,6)),'Lançamento'!C9,0) | D9: =IF(AND(ISNUMBER('Lançamento'!D9),ROUND('Lançamento'!D9,6)>=ROUND('Lançamento'!$H$3,6)),'Lançamento'!D9,0) | E9: =IF(AND(ISNUMBER('Lançamento'!E9),ROUND('Lançamento'!E9,6)>=ROUND('Lançamento'!$H$3,6)),'Lançamento'!E9,0) | F9: =IF(AND(ISNUMBER('Lançamento'!F9),ROUND('Lançamento'!F9,6)>=ROUND('Lançamento'!$H$3,6)),'Lançamento'!F9,0) | G9: =IF(AND(ISNUMBER('Lançamento'!G9),ROUND('Lançamento'!G9,6)>=ROUND('Lançamento'!$H$3,6)),'Lançamento'!G9,0) | H9: =IF(AND(ISNUMBER('Lançamento'!H9),ROUND('Lançamento'!H9,6)>=ROUND('Lançamento'!$H$3,6)),'Lançamento'!H9,0) | I9: =IF(AND(ISNUMBER('Lançamento'!I9),ROUND('Lançamento'!I9,6)>=ROUND('Lançamento'!$H$3,6)),'Lançamento'!I9,0) | ... M9: =IF(AND(ISNUMBER('Lançamento'!M9),ROUND('Lançamento'!M9,6)>=ROUND('Lançamento'!$H$3,6)),'Lançamento'!M9,0) | N9: =IF(AND(ISNUMBER('Lançamento'!B9),ROUND('Lançamento'!B9,6)<ROUND('Lançamento'!$H$3,6),ROUND('Lançamento'!B9,6)>=ROUND('Lançamento'!$K$3,6)),'Lançamento'!B9,0) | O9: =IF(AND(ISNUMBER('Lançamento'!C9),ROUND('Lançamento'!C9,6)<ROUND('Lançamento'!$H$3,6),ROUND('Lançamento'!C9,6)>=ROUND('Lançamento'!$K$3,6)),'Lançamento'!C9,0) | P9: =IF(AND(ISNUMBER('Lançamento'!D9),ROUND('Lançamento'!D9,6)<ROUND('Lançamento'!$H$3,6),ROUND('Lançamento'!D9,6)>=ROUND('Lançamento'!$K$3,6)),'Lançamento'!D9,0) | Q9: =IF(AND(ISNUMBER('Lançamento'!E9),ROUND('Lançamento'!E9,6)<ROUND('Lançamento'!$H$3,6),ROUND('Lançamento'!E9,6)>=ROUND('Lançamento'!$K$3,6)),'Lançamento'!E9,0) | R9: =IF(AND(ISNUMBER('Lançamento'!F9),ROUND('Lançamento'!F9,6)<ROUND('Lançamento'!$H$3,6),ROUND('Lançamento'!F9,6)>=ROUND('Lançamento'!$K$3,6)),'Lançamento'!F9,0) | S9: =IF(AND(ISNUMBER('Lançamento'!G9),ROUND('Lançamento'!G9,6)<ROUND('Lançamento'!$H$3,6),ROUND('Lançamento'!G9,6)>=ROUND('Lançamento'!$K$3,6)),'Lançamento'!G9,0) | T9: =IF(AND(ISNUMBER('Lançamento'!H9),ROUND('Lançamento'!H9,6)<ROUND('Lançamento'!$H$3,6),ROUND('Lançamento'!H9,6)>=ROUND('Lançamento'!$K$3,6)),'Lançamento'!H9,0) | U9: =IF(AND(ISNUMBER('Lançamento'!I9),ROUND('Lançamento'!I9,6)<ROUND('Lançamento'!$H$3,6),ROUND('Lançamento'!I9,6)>=ROUND('Lançamento'!$K$3,6)),'Lançamento'!I9,0) | ... Y9: =IF(AND(ISNUMBER('Lançamento'!M9),ROUND('Lançamento'!M9,6)<ROUND('Lançamento'!$H$3,6),ROUND('Lançamento'!M9,6)>=ROUND('Lançamento'!$K$3,6)),'Lançamento'!M9,0) | Z9: =IF(AND(ISNUMBER('Lançamento'!B9),ROUND('Lançamento'!B9,6)<ROUND('Lançamento'!$K$3,6)),'Lançamento'!B9,0) | AA9: =IF(AND(ISNUMBER('Lançamento'!C9),ROUND('Lançamento'!C9,6)<ROUND('Lançamento'!$K$3,6)),'Lançamento'!C9,0) | AB9: =IF(AND(ISNUMBER('Lançamento'!D9),ROUND('Lançamento'!D9,6)<ROUND('Lançamento'!$K$3,6)),'Lançamento'!D9,0) | AC9: =IF(AND(ISNUMBER('Lançamento'!E9),ROUND('Lançamento'!E9,6)<ROUND('Lançamento'!$K$3,6)),'Lançamento'!E9,0) | AD9: =IF(AND(ISNUMBER('Lançamento'!F9),ROUND('Lançamento'!F9,6)<ROUND('Lançamento'!$K$3,6)),'Lançamento'!F9,0) | AE9: =IF(AND(ISNUMBER('Lançamento'!G9),ROUND('Lançamento'!G9,6)<ROUND('Lançamento'!$K$3,6)),'Lançamento'!G9,0) | AF9: =IF(AND(ISNUMBER('Lançamento'!H9),ROUND('Lançamento'!H9,6)<ROUND('Lançamento'!$K$3,6)),'Lançamento'!H9,0) | AG9: =IF(AND(ISNUMBER('Lançamento'!I9),ROUND('Lançamento'!I9,6)<ROUND('Lançamento'!$K$3,6)),'Lançamento'!I9,0) | ... AK9: =IF(AND(ISNUMBER('Lançamento'!M9),ROUND('Lançamento'!M9,6)<ROUND('Lançamento'!$K$3,6)),'Lançamento'!M9,0) | AL9: =IF(ISNUMBER('Lançamento'!$N9),'Lançamento'!$N9,0) | AM9: =IF(ISNUMBER('Lançamento'!$N9),'Lançamento'!$N9,0) | AN9: =IF(ISNUMBER('Lançamento'!$N9),'Lançamento'!$N9,0) | AO9: =IF(ISNUMBER('Lançamento'!$N9),'Lançamento'!$N9,0) | AP9: =IF(ISNUMBER('Lançamento'!$N9),'Lançamento'!$N9,0) | AQ9: =IF(ISNUMBER('Lançamento'!$N9),'Lançamento'!$N9,0) | AR9: =IF(ISNUMBER('Lançamento'!$N9),'Lançamento'!$N9,0) | AS9: =IF(ISNUMBER('Lançamento'!$N9),'Lançamento'!$N9,0) | ... AW9: =IF(ISNUMBER('Lançamento'!$N9),'Lançamento'!$N9,0) | AX9: =NA() | AY9: =NA() | AZ9: =IF(COUNT('Lançamento'!B9:'Lançamento'!D9)=3,AVERAGE('Lançamento'!B9:'Lançamento'!D9),NA()) | BA9: =IF(COUNT('Lançamento'!C9:'Lançamento'!E9)=3,AVERAGE('Lançamento'!C9:'Lançamento'!E9),NA()) | BB9: =IF(COUNT('Lançamento'!D9:'Lançamento'!F9)=3,AVERAGE('Lançamento'!D9:'Lançamento'!F9),NA()) | BC9: =IF(COUNT('Lançamento'!E9:'Lançamento'!G9)=3,AVERAGE('Lançamento'!E9:'Lançamento'!G9),NA()) | BD9: =IF(COUNT('Lançamento'!F9:'Lançamento'!H9)=3,AVERAGE('Lançamento'!F9:'Lançamento'!H9),NA()) | BE9: =IF(COUNT('Lançamento'!G9:'Lançamento'!I9)=3,AVERAGE('Lançamento'!G9:'Lançamento'!I9),NA()) | BF9: =IF(COUNT('Lançamento'!H9:'Lançamento'!J9)=3,AVERAGE('Lançamento'!H9:'Lançamento'!J9),NA()) | BG9: =IF(COUNT('Lançamento'!I9:'Lançamento'!K9)=3,AVERAGE('Lançamento'!I9:'Lançamento'!K9),NA()) | ... BI9: =IF(COUNT('Lançamento'!K9:'Lançamento'!M9)=3,AVERAGE('Lançamento'!K9:'Lançamento'!M9),NA()) | BJ9: =IF('Lançamento'!A9="","",'Lançamento'!A9&" | Média YTD: "&IF('Lançamento'!O9="","-",ROUND('Lançamento'!O9*100,1)&"%"))
A10: =IF('Lançamento'!A10="","",'Lançamento'!A10) | B10: =IF(AND(ISNUMBER('Lançamento'!B10),ROUND('Lançamento'!B10,6)>=ROUND('Lançamento'!$H$3,6)),'Lançamento'!B10,0) | C10: =IF(AND(ISNUMBER('Lançamento'!C10),ROUND('Lançamento'!C10,6)>=ROUND('Lançamento'!$H$3,6)),'Lançamento'!C10,0) | D10: =IF(AND(ISNUMBER('Lançamento'!D10),ROUND('Lançamento'!D10,6)>=ROUND('Lançamento'!$H$3,6)),'Lançamento'!D10,0) | E10: =IF(AND(ISNUMBER('Lançamento'!E10),ROUND('Lançamento'!E10,6)>=ROUND('Lançamento'!$H$3,6)),'Lançamento'!E10,0) | F10: =IF(AND(ISNUMBER('Lançamento'!F10),ROUND('Lançamento'!F10,6)>=ROUND('Lançamento'!$H$3,6)),'Lançamento'!F10,0) | G10: =IF(AND(ISNUMBER('Lançamento'!G10),ROUND('Lançamento'!G10,6)>=ROUND('Lançamento'!$H$3,6)),'Lançamento'!G10,0) | H10: =IF(AND(ISNUMBER('Lançamento'!H10),ROUND('Lançamento'!H10,6)>=ROUND('Lançamento'!$H$3,6)),'Lançamento'!H10,0) | I10: =IF(AND(ISNUMBER('Lançamento'!I10),ROUND('Lançamento'!I10,6)>=ROUND('Lançamento'!$H$3,6)),'Lançamento'!I10,0) | ... M10: =IF(AND(ISNUMBER('Lançamento'!M10),ROUND('Lançamento'!M10,6)>=ROUND('Lançamento'!$H$3,6)),'Lançamento'!M10,0) | N10: =IF(AND(ISNUMBER('Lançamento'!B10),ROUND('Lançamento'!B10,6)<ROUND('Lançamento'!$H$3,6),ROUND('Lançamento'!B10,6)>=ROUND('Lançamento'!$K$3,6)),'Lançamento'!B10,0) | O10: =IF(AND(ISNUMBER('Lançamento'!C10),ROUND('Lançamento'!C10,6)<ROUND('Lançamento'!$H$3,6),ROUND('Lançamento'!C10,6)>=ROUND('Lançamento'!$K$3,6)),'Lançamento'!C10,0) | P10: =IF(AND(ISNUMBER('Lançamento'!D10),ROUND('Lançamento'!D10,6)<ROUND('Lançamento'!$H$3,6),ROUND('Lançamento'!D10,6)>=ROUND('Lançamento'!$K$3,6)),'Lançamento'!D10,0) | Q10: =IF(AND(ISNUMBER('Lançamento'!E10),ROUND('Lançamento'!E10,6)<ROUND('Lançamento'!$H$3,6),ROUND('Lançamento'!E10,6)>=ROUND('Lançamento'!$K$3,6)),'Lançamento'!E10,0) | R10: =IF(AND(ISNUMBER('Lançamento'!F10),ROUND('Lançamento'!F10,6)<ROUND('Lançamento'!$H$3,6),ROUND('Lançamento'!F10,6)>=ROUND('Lançamento'!$K$3,6)),'Lançamento'!F10,0) | S10: =IF(AND(ISNUMBER('Lançamento'!G10),ROUND('Lançamento'!G10,6)<ROUND('Lançamento'!$H$3,6),ROUND('Lançamento'!G10,6)>=ROUND('Lançamento'!$K$3,6)),'Lançamento'!G10,0) | T10: =IF(AND(ISNUMBER('Lançamento'!H10),ROUND('Lançamento'!H10,6)<ROUND('Lançamento'!$H$3,6),ROUND('Lançamento'!H10,6)>=ROUND('Lançamento'!$K$3,6)),'Lançamento'!H10,0) | U10: =IF(AND(ISNUMBER('Lançamento'!I10),ROUND('Lançamento'!I10,6)<ROUND('Lançamento'!$H$3,6),ROUND('Lançamento'!I10,6)>=ROUND('Lançamento'!$K$3,6)),'Lançamento'!I10,0) | ... Y10: =IF(AND(ISNUMBER('Lançamento'!M10),ROUND('Lançamento'!M10,6)<ROUND('Lançamento'!$H$3,6),ROUND('Lançamento'!M10,6)>=ROUND('Lançamento'!$K$3,6)),'Lançamento'!M10,0) | Z10: =IF(AND(ISNUMBER('Lançamento'!B10),ROUND('Lançamento'!B10,6)<ROUND('Lançamento'!$K$3,6)),'Lançamento'!B10,0) | AA10: =IF(AND(ISNUMBER('Lançamento'!C10),ROUND('Lançamento'!C10,6)<ROUND('Lançamento'!$K$3,6)),'Lançamento'!C10,0) | AB10: =IF(AND(ISNUMBER('Lançamento'!D10),ROUND('Lançamento'!D10,6)<ROUND('Lançamento'!$K$3,6)),'Lançamento'!D10,0) | AC10: =IF(AND(ISNUMBER('Lançamento'!E10),ROUND('Lançamento'!E10,6)<ROUND('Lançamento'!$K$3,6)),'Lançamento'!E10,0) | AD10: =IF(AND(ISNUMBER('Lançamento'!F10),ROUND('Lançamento'!F10,6)<ROUND('Lançamento'!$K$3,6)),'Lançamento'!F10,0) | AE10: =IF(AND(ISNUMBER('Lançamento'!G10),ROUND('Lançamento'!G10,6)<ROUND('Lançamento'!$K$3,6)),'Lançamento'!G10,0) | AF10: =IF(AND(ISNUMBER('Lançamento'!H10),ROUND('Lançamento'!H10,6)<ROUND('Lançamento'!$K$3,6)),'Lançamento'!H10,0) | AG10: =IF(AND(ISNUMBER('Lançamento'!I10),ROUND('Lançamento'!I10,6)<ROUND('Lançamento'!$K$3,6)),'Lançamento'!I10,0) | ... AK10: =IF(AND(ISNUMBER('Lançamento'!M10),ROUND('Lançamento'!M10,6)<ROUND('Lançamento'!$K$3,6)),'Lançamento'!M10,0) | AL10: =IF(ISNUMBER('Lançamento'!$N10),'Lançamento'!$N10,0) | AM10: =IF(ISNUMBER('Lançamento'!$N10),'Lançamento'!$N10,0) | AN10: =IF(ISNUMBER('Lançamento'!$N10),'Lançamento'!$N10,0) | AO10: =IF(ISNUMBER('Lançamento'!$N10),'Lançamento'!$N10,0) | AP10: =IF(ISNUMBER('Lançamento'!$N10),'Lançamento'!$N10,0) | AQ10: =IF(ISNUMBER('Lançamento'!$N10),'Lançamento'!$N10,0) | AR10: =IF(ISNUMBER('Lançamento'!$N10),'Lançamento'!$N10,0) | AS10: =IF(ISNUMBER('Lançamento'!$N10),'Lançamento'!$N10,0) | ... AW10: =IF(ISNUMBER('Lançamento'!$N10),'Lançamento'!$N10,0) | AX10: =NA() | AY10: =NA() | AZ10: =IF(COUNT('Lançamento'!B10:'Lançamento'!D10)=3,AVERAGE('Lançamento'!B10:'Lançamento'!D10),NA()) | BA10: =IF(COUNT('Lançamento'!C10:'Lançamento'!E10)=3,AVERAGE('Lançamento'!C10:'Lançamento'!E10),NA()) | BB10: =IF(COUNT('Lançamento'!D10:'Lançamento'!F10)=3,AVERAGE('Lançamento'!D10:'Lançamento'!F10),NA()) | BC10: =IF(COUNT('Lançamento'!E10:'Lançamento'!G10)=3,AVERAGE('Lançamento'!E10:'Lançamento'!G10),NA()) | BD10: =IF(COUNT('Lançamento'!F10:'Lançamento'!H10)=3,AVERAGE('Lançamento'!F10:'Lançamento'!H10),NA()) | BE10: =IF(COUNT('Lançamento'!G10:'Lançamento'!I10)=3,AVERAGE('Lançamento'!G10:'Lançamento'!I10),NA()) | BF10: =IF(COUNT('Lançamento'!H10:'Lançamento'!J10)=3,AVERAGE('Lançamento'!H10:'Lançamento'!J10),NA()) | BG10: =IF(COUNT('Lançamento'!I10:'Lançamento'!K10)=3,AVERAGE('Lançamento'!I10:'Lançamento'!K10),NA()) | ... BI10: =IF(COUNT('Lançamento'!K10:'Lançamento'!M10)=3,AVERAGE('Lançamento'!K10:'Lançamento'!M10),NA()) | BJ10: =IF('Lançamento'!A10="","",'Lançamento'!A10&" | Média YTD: "&IF('Lançamento'!O10="","-",ROUND('Lançamento'!O10*100,1)&"%"))
A11: =IF('Lançamento'!A11="","",'Lançamento'!A11) | B11: =IF(AND(ISNUMBER('Lançamento'!B11),ROUND('Lançamento'!B11,6)>=ROUND('Lançamento'!$H$3,6)),'Lançamento'!B11,0) | C11: =IF(AND(ISNUMBER('Lançamento'!C11),ROUND('Lançamento'!C11,6)>=ROUND('Lançamento'!$H$3,6)),'Lançamento'!C11,0) | D11: =IF(AND(ISNUMBER('Lançamento'!D11),ROUND('Lançamento'!D11,6)>=ROUND('Lançamento'!$H$3,6)),'Lançamento'!D11,0) | E11: =IF(AND(ISNUMBER('Lançamento'!E11),ROUND('Lançamento'!E11,6)>=ROUND('Lançamento'!$H$3,6)),'Lançamento'!E11,0) | F11: =IF(AND(ISNUMBER('Lançamento'!F11),ROUND('Lançamento'!F11,6)>=ROUND('Lançamento'!$H$3,6)),'Lançamento'!F11,0) | G11: =IF(AND(ISNUMBER('Lançamento'!G11),ROUND('Lançamento'!G11,6)>=ROUND('Lançamento'!$H$3,6)),'Lançamento'!G11,0) | H11: =IF(AND(ISNUMBER('Lançamento'!H11),ROUND('Lançamento'!H11,6)>=ROUND('Lançamento'!$H$3,6)),'Lançamento'!H11,0) | I11: =IF(AND(ISNUMBER('Lançamento'!I11),ROUND('Lançamento'!I11,6)>=ROUND('Lançamento'!$H$3,6)),'Lançamento'!I11,0) | ... M11: =IF(AND(ISNUMBER('Lançamento'!M11),ROUND('Lançamento'!M11,6)>=ROUND('Lançamento'!$H$3,6)),'Lançamento'!M11,0) | N11: =IF(AND(ISNUMBER('Lançamento'!B11),ROUND('Lançamento'!B11,6)<ROUND('Lançamento'!$H$3,6),ROUND('Lançamento'!B11,6)>=ROUND('Lançamento'!$K$3,6)),'Lançamento'!B11,0) | O11: =IF(AND(ISNUMBER('Lançamento'!C11),ROUND('Lançamento'!C11,6)<ROUND('Lançamento'!$H$3,6),ROUND('Lançamento'!C11,6)>=ROUND('Lançamento'!$K$3,6)),'Lançamento'!C11,0) | P11: =IF(AND(ISNUMBER('Lançamento'!D11),ROUND('Lançamento'!D11,6)<ROUND('Lançamento'!$H$3,6),ROUND('Lançamento'!D11,6)>=ROUND('Lançamento'!$K$3,6)),'Lançamento'!D11,0) | Q11: =IF(AND(ISNUMBER('Lançamento'!E11),ROUND('Lançamento'!E11,6)<ROUND('Lançamento'!$H$3,6),ROUND('Lançamento'!E11,6)>=ROUND('Lançamento'!$K$3,6)),'Lançamento'!E11,0) | R11: =IF(AND(ISNUMBER('Lançamento'!F11),ROUND('Lançamento'!F11,6)<ROUND('Lançamento'!$H$3,6),ROUND('Lançamento'!F11,6)>=ROUND('Lançamento'!$K$3,6)),'Lançamento'!F11,0) | S11: =IF(AND(ISNUMBER('Lançamento'!G11),ROUND('Lançamento'!G11,6)<ROUND('Lançamento'!$H$3,6),ROUND('Lançamento'!G11,6)>=ROUND('Lançamento'!$K$3,6)),'Lançamento'!G11,0) | T11: =IF(AND(ISNUMBER('Lançamento'!H11),ROUND('Lançamento'!H11,6)<ROUND('Lançamento'!$H$3,6),ROUND('Lançamento'!H11,6)>=ROUND('Lançamento'!$K$3,6)),'Lançamento'!H11,0) | U11: =IF(AND(ISNUMBER('Lançamento'!I11),ROUND('Lançamento'!I11,6)<ROUND('Lançamento'!$H$3,6),ROUND('Lançamento'!I11,6)>=ROUND('Lançamento'!$K$3,6)),'Lançamento'!I11,0) | ... Y11: =IF(AND(ISNUMBER('Lançamento'!M11),ROUND('Lançamento'!M11,6)<ROUND('Lançamento'!$H$3,6),ROUND('Lançamento'!M11,6)>=ROUND('Lançamento'!$K$3,6)),'Lançamento'!M11,0) | Z11: =IF(AND(ISNUMBER('Lançamento'!B11),ROUND('Lançamento'!B11,6)<ROUND('Lançamento'!$K$3,6)),'Lançamento'!B11,0) | AA11: =IF(AND(ISNUMBER('Lançamento'!C11),ROUND('Lançamento'!C11,6)<ROUND('Lançamento'!$K$3,6)),'Lançamento'!C11,0) | AB11: =IF(AND(ISNUMBER('Lançamento'!D11),ROUND('Lançamento'!D11,6)<ROUND('Lançamento'!$K$3,6)),'Lançamento'!D11,0) | AC11: =IF(AND(ISNUMBER('Lançamento'!E11),ROUND('Lançamento'!E11,6)<ROUND('Lançamento'!$K$3,6)),'Lançamento'!E11,0) | AD11: =IF(AND(ISNUMBER('Lançamento'!F11),ROUND('Lançamento'!F11,6)<ROUND('Lançamento'!$K$3,6)),'Lançamento'!F11,0) | AE11: =IF(AND(ISNUMBER('Lançamento'!G11),ROUND('Lançamento'!G11,6)<ROUND('Lançamento'!$K$3,6)),'Lançamento'!G11,0) | AF11: =IF(AND(ISNUMBER('Lançamento'!H11),ROUND('Lançamento'!H11,6)<ROUND('Lançamento'!$K$3,6)),'Lançamento'!H11,0) | AG11: =IF(AND(ISNUMBER('Lançamento'!I11),ROUND('Lançamento'!I11,6)<ROUND('Lançamento'!$K$3,6)),'Lançamento'!I11,0) | ... AK11: =IF(AND(ISNUMBER('Lançamento'!M11),ROUND('Lançamento'!M11,6)<ROUND('Lançamento'!$K$3,6)),'Lançamento'!M11,0) | AL11: =IF(ISNUMBER('Lançamento'!$N11),'Lançamento'!$N11,0) | AM11: =IF(ISNUMBER('Lançamento'!$N11),'Lançamento'!$N11,0) | AN11: =IF(ISNUMBER('Lançamento'!$N11),'Lançamento'!$N11,0) | AO11: =IF(ISNUMBER('Lançamento'!$N11),'Lançamento'!$N11,0) | AP11: =IF(ISNUMBER('Lançamento'!$N11),'Lançamento'!$N11,0) | AQ11: =IF(ISNUMBER('Lançamento'!$N11),'Lançamento'!$N11,0) | AR11: =IF(ISNUMBER('Lançamento'!$N11),'Lançamento'!$N11,0) | AS11: =IF(ISNUMBER('Lançamento'!$N11),'Lançamento'!$N11,0) | ... AW11: =IF(ISNUMBER('Lançamento'!$N11),'Lançamento'!$N11,0) | AX11: =NA() | AY11: =NA() | AZ11: =IF(COUNT('Lançamento'!B11:'Lançamento'!D11)=3,AVERAGE('Lançamento'!B11:'Lançamento'!D11),NA()) | BA11: =IF(COUNT('Lançamento'!C11:'Lançamento'!E11)=3,AVERAGE('Lançamento'!C11:'Lançamento'!E11),NA()) | BB11: =IF(COUNT('Lançamento'!D11:'Lançamento'!F11)=3,AVERAGE('Lançamento'!D11:'Lançamento'!F11),NA()) | BC11: =IF(COUNT('Lançamento'!E11:'Lançamento'!G11)=3,AVERAGE('Lançamento'!E11:'Lançamento'!G11),NA()) | BD11: =IF(COUNT('Lançamento'!F11:'Lançamento'!H11)=3,AVERAGE('Lançamento'!F11:'Lançamento'!H11),NA()) | BE11: =IF(COUNT('Lançamento'!G11:'Lançamento'!I11)=3,AVERAGE('Lançamento'!G11:'Lançamento'!I11),NA()) | BF11: =IF(COUNT('Lançamento'!H11:'Lançamento'!J11)=3,AVERAGE('Lançamento'!H11:'Lançamento'!J11),NA()) | BG11: =IF(COUNT('Lançamento'!I11:'Lançamento'!K11)=3,AVERAGE('Lançamento'!I11:'Lançamento'!K11),NA()) | ... BI11: =IF(COUNT('Lançamento'!K11:'Lançamento'!M11)=3,AVERAGE('Lançamento'!K11:'Lançamento'!M11),NA()) | BJ11: =IF('Lançamento'!A11="","",'Lançamento'!A11&" | Média YTD: "&IF('Lançamento'!O11="","-",ROUND('Lançamento'!O11*100,1)&"%"))
